Workbook

Sheet Master_Claims_Register
A1: S.No. | B1: Claim_ID | C1: Creditor_Name | D1: Creditor_Type | E1: Sub_Category | F1: Claim_Amount_INR | G1: Verified_Amount_INR | H1: Disputed_Amount_INR | I1: Date_of_Claim | J1: Verification_Date | K1: Status | L1: Priority_Rank | M1: Resolution_Plan | N1: Assigned_Officer | O1: Remarks | P1: Last_Updated
A2: 1 | B2: CR-001 | C2: State Bank of India | D2: Financial | E2: Term Loan | F2: 500000000 | G2: 492016900 | H2: 7983100 | I2: 10-Oct-2024 | J2: 10-Feb-2026 | K2: Admitted | L2: 1 | M2: Haircut Negotiation | N2: M. Jain | P2: 23-Mar-2026
A3: 2 | B3: CR-002 | C3: Punjab National Bank | D3: Financial | E3: Working Capital | F3: 300000000 | G3: 223149209 | H3: 76850791 | I3: 15-Nov-2024 | J3: 01-Jan-2026 | K3: Admitted | L3: 2 | M3: Liquidation Value | N3: A. Verma | P3: 23-Mar-2026
A4: 3 | B4: CR-003 | C4: HDFC Bank | D4: Financial | E4: Term Loan | F4: 250000000 | G4: 245299481 | H4: 4700519 | I4: 20-Dec-2024 | J4: 01-Mar-2026 | K4: Admitted | L4: 3 | M4: Resolution Plan B | N4: K. Patel | P4: 23-Mar-2026
A5: 4 | B5: CR-004 | C5: ICICI Bank | D5: Financial | E5: Cash Credit | F5: 150000000 | G5: 129361263 | H5: 20638737 | I5: 05-Jan-2025 | J5: 28-Feb-2026 | K5: Admitted | L5: 4 | M5: Liquidation Value | N5: S. Gupta | P5: 23-Mar-2026
A6: 5 | B6: CR-005 | C6: Axis Bank | D6: Financial | E6: Overdraft | F6: 100000000 | G6: 95873539 | H6: 4126461 | I6: 10-Feb-2025 | J6: 08-Dec-2025 | K6: Admitted | L6: 5 | M6: Going Concern | N6: N. Singh | P6: 23-Mar-2026
A7: 6 | B7: CR-006 | C7: Bank of Baroda | D7: Financial | E7: Term Loan | F7: 200000000 | G7: 157053122 | H7: 42946878 | I7: 15-Mar-2025 | J7: 29-Jan-2026 | K7: Admitted | L7: 6 | M7: Tribunal Order | N7: A. Verma | P7: 23-Mar-2026
A8: 7 | B8: CR-007 | C8: Union Bank | D8: Financial | E8: Working Capital | F8: 120000000 | G8: 102744855 | H8: 17255145 | I8: 20-Apr-2025 | J8: 02-Jan-2026 | K8: Admitted | L8: 7 | M8: Haircut Negotiation | N8: S. Gupta | P8: 23-Mar-2026
A9: 8 | B9: CR-008 | C9: Canara Bank | D9: Financial | E9: Cash Credit | F9: 180000000 | G9: 143541502 | H9: 36458498 | I9: 25-May-2025 | J9: 15-Feb-2026 | K9: Admitted | L9: 8 | M9: Going Concern | N9: A. Verma | P9: 23-Mar-2026
A10: 9 | B10: CR-009 | C10: Kotak Mahindra Bank | D10: Financial | E10: Overdraft | F10: 90000000 | G10: 78861269 | H10: 11138731 | I10: 30-Jun-2025 | J10: 11-Dec-2025 | K10: Admitted | L10: 9 | M10: Resolution Plan A | N10: M. Jain | P10: 23-Mar-2026
A11: 10 | B11: CR-010 | C11: IndusInd Bank | D11: Financial | E11: Term Loan | F11: 75000000 | G11: 61539816 | H11: 13460184 | I11: 05-Jul-2025 | J11: 01-Feb-2026 | K11: Admitted | L11: 10 | M11: Resolution Plan A | N11: N. Singh | P11: 23-Mar-2026
A12: 11 | B12: CR-011 | C12: Alpha Steel Suppliers | D12: Operational | E12: Raw Material Supply | F12: 5000000 | G12: 4567289 | H12: 432711 | I12: 12-Aug-2025 | J12: 20-Dec-2025 | K12: Under Review | L12: 11 | M12: Resolution Plan A | N12: P. Kumar | P12: 23-Mar-2026
A13: 12 | B13: CR-012 | C13: Beta Cement Co. | D13: Operational | E13: Construction Material | F13: 3000000 | G13: 2782909 | H13: 217091 | I13: 18-Aug-2025 | J13: 26-Feb-2026 | K13: Under Review | L13: 12 | M13: Haircut Negotiation | N13: P. Kumar | P13: 23-Mar-2026
... A90: 89 | B90: CR-089 | C90: Supplier_74 | D90: Operational | E90: Insurance | F90: 600000 | G90: 458323 | H90: 141677 | I90: 28-Nov-2025 | J90: 29-Jan-2026 | K90: Pending | L90: 89 | M90: Resolution Plan B | N90: P. Kumar | P90: 23-Mar-2026
A91: 90 | B91: CR-090 | C91: Supplier_75 | D91: Operational | E91: Raw Material | F91: 1200000 | G91: 1046339 | H91: 153661 | I91: 45990 | J91: 14-Feb-2026 | K91: Pending | L91: 90 | M91: Tribunal Order | N91: A. Verma | P91: 23-Mar-2026
A92: 91 | B92: CR-091 | C92: State Govt GST Department | D92: Statutory Dues | E92: GST Arrears | F92: 45000000 | G92: 42713901 | H92: 2286099 | I92: 45996 | J92: 21-Feb-2026 | K92: Attached | L92: 91 | M92: Going Concern | N92: A. Verma | P92: 23-Mar-2026
A93: 92 | B93: CR-092 | C93: Income Tax Department - Assessment Wing | D93: Statutory Dues | E93: IT Assessment AY 2020-21 | F93: 250000000 | G93: 240954091 | H93: 9045909 | I93: 46037 | J93: 01-Feb-2026 | K93: Provisional Attachment | L93: 92 | M93: Liquidation Value | N93: N. Singh | P93: 23-Mar-2026
A94: 93 | B94: CR-094 | C94: SEBI Penalty Division | D94: Statutory Dues | E94: SEBI Penalty Order | F94: 15000000 | G94: 12927404 | H94: 2072596 | I94: 46011 | J94: 21-Jan-2026 | K94: Pending | L94: 93 | M94: Liquidation Value | N94: P. Kumar | P94: 23-Mar-2026
A95: 94 | B95: CR-100 | C95: Income Tax Department - TDS Division | D95: Statutory Dues | E95: TDS Default FY 2019-20 | F95: 35000000 | G95: 30244831 | H95: 4755169 | I95: 46042 | J95: 01-Dec-2025 | K95: Under Review | L95: 94 | M95: Haircut Negotiation | N95: S. Gupta | P95: 23-Mar-2026
A96: 95 | B96: CR-101 | C96: Income Tax Department - Penalty Wing | D96: Statutory Dues | E96: IT Penalty u/s 271(1)(c) | F96: 18000000 | G96: 17181070 | H96: 818930 | I96: 46047 | J96: 02-Dec-2025 | K96: Disputed | L96: 95 | M96: Resolution Plan A | N96: M. Jain | P96: 23-Mar-2026
A97: 96 | B97: CR-102 | C97: Income Tax Department - Recovery Unit | D97: Statutory Dues | E97: IT Recovery AY 2021-22 | F97: 42000000 | G97: 34681088 | H97: 7318912 | I97: 46054 | J97: 15-Jan-2026 | K97: Notice Issued | L97: 96 | M97: Haircut Negotiation | N97: N. Singh | P97: 23-Mar-2026
A98: 97 | B98: CR-103 | C98: Income Tax Department - Assessment Wing | D98: Statutory Dues | E98: IT Assessment AY 2022-23 | F98: 55000000 | G98: 49785783 | H98: 5214217 | I98: 46058 | J98: 05-Feb-2026 | K98: Provisional Attachment | L98: 97 | M98: Tribunal Order | N98: M. Jain | P98: 23-Mar-2026
A99: 98 | B99: CR-104 | C99: Income Tax Department - International Tax | D99: Statutory Dues | E99: Transfer Pricing Adjustment | F99: 120000000 | G99: 119989008 | H99: 10992 | I99: 46063 | J99: 03-Jan-2026 | K99: Under Appeal | L99: 98 | M99: Pending Decision | N99: R. Sharma IRP | P99: 23-Mar-2026
A100: 99 | B100: CR-105 | C100: Income Tax Department - TDS Division | D100: Statutory Dues | E100: TDS Short Deduction FY 2020-21 | F100: 28000000 | G100: 27451818 | H100: 548182 | I100: 45976 | J100: 09-Jan-2026 | K100: Under Review | L100: 99 | M100: Going Concern | N100: N. Singh | P100: 23-Mar-2026
A101: 100 | B101: CR-106 | C101: Income Tax Department - Reassessment Cell | D101: Statutory Dues | E101: Reassessment u/s 148 AY 2019-20 | F101: 75000000 | G101: 72261153 | H101: 2738847 | I101: 46073 | J101: 28-Dec-2025 | K101: Notice Issued | L101: 100 | M101: Going Concern | N101: D. Rao | P101: 23-Mar-2026
A102: 101 | B102: CR-107 | C102: Income Tax Department - Penalty Wing | D102: Statutory Dues | E102: Concealment Penalty AY 2021-22 | F102: 32000000 | G102: 31812249 | H102: 187751 | I102: 45986 | J102: 24-Jan-2026 | K102: Disputed | L102: 101 | M102: Resolution Plan B | N102: P. Kumar | P102: 23-Mar-2026
... A108: 107 | B108: CR-113 | C108: Customs Department | D108: Statutory Dues | E108: Customs Duty Differential | F108: 12000000 | G108: 10209180 | H108: 1790820 | I108: 46099 | J108: 14-Dec-2025 | K108: Pending | L108: 107 | M108: Tribunal Order | N108: S. Gupta | P108: 23-Mar-2026
A109: 108 | B109: CR-114 | C109: EPF Commissioner | D109: Statutory Dues | E109: PF Default | F109: 8000000 | G109: 5788284 | H109: 2211716 | I109: 20-Mar-2026 | J109: 25-Feb-2026 | K109: Under Review | L109: 108 | M109: Resolution Plan B | N109: S. Gupta | P109: 23-Mar-2026
A110: 109 | B110: CR-115 | C110: ESI Corporation | D110: Statutory Dues | E110: ESI Arrears | F110: 3500000 | G110: 3484361 | H110: 15639 | I110: 22-Mar-2026 | J110: 21-Dec-2025 | K110: Under Review | L110: 109 | M110: Tribunal Order | N110: K. Patel | P110: 23-Mar-2026
A111: 110 | B111: CR-120 | C111: General Workers Union | D111: Workmen Dues | E111: Wages & Benefits | F111: 500000 | G111: 352262 | H111: 147738 | I111: 01-Dec-2025 | J111: 19-Feb-2026 | K111: Under Review | L111: 110 | M111: Resolution Plan A | N111: R. Sharma IRP | P111: 23-Mar-2026
A112: 111 | B112: CR-121 | C112: Technical Staff Association | D112: Workmen Dues | E112: Wages & Benefits | F112: 700000 | G112: 618663 | H112: 81337 | I112: 02-Dec-2025 | J112: 25-Feb-2026 | K112: Under Review | L112: 111 | M112: Going Concern | N112: M. Jain | P112: 23-Mar-2026
A113: 112 | B113: CR-122 | C113: Contract Labour Federation | D113: Workmen Dues | E113: Wages & Benefits | F113: 2000000 | G113: 1541477 | H113: 458523 | I113: 03-Dec-2025 | J113: 15-Dec-2025 | K113: Under Review | L113: 112 | M113: Haircut Negotiation | N113: N. Singh | P113: 23-Mar-2026
A114: 113 | B114: CR-123 | C114: Plant Workers Collective | D114: Workmen Dues | E114: Wages & Benefits | F114: 700000 | G114: 670515 | H114: 29485 | I114: 04-Dec-2025 | J114: 10-Jan-2026 | K114: Under Review | L114: 113 | M114: Going Concern | N114: S. Gupta | P114: 23-Mar-2026
A115: 114 | B115: CR-124 | C115: Maintenance Staff Union | D115: Workmen Dues | E115: Wages & Benefits | F115: 8000000 | G115: 7141150 | H115: 858850 | I115: 05-Dec-2025 | J115: 17-Feb-2026 | K115: Under Review | L115: 114 | M115: Tribunal Order | N115: M. Jain | P115: 23-Mar-2026
A116: 115 | B116: CR-125 | C116: Transport Workers Guild | D116: Workmen Dues | E116: Wages & Benefits | F116: 700000 | G116: 618411 | H116: 81589 | I116: 06-Dec-2025 | J116: 11-Feb-2026 | K116: Under Review | L116: 115 | M116: Settlement | N116: D. Rao | P116: 23-Mar-2026
A117: 116 | B117: CR-126 | C117: Security Personnel Association | D117: Workmen Dues | E117: Wages & Benefits | F117: 5000000 | G117: 3721423 | H117: 1278577 | I117: 07-Dec-2025 | J117: 21-Jan-2026 | K117: Under Review | L117: 116 | M117: Pending Decision | N117: N. Singh | P117: 23-Mar-2026
A118: 117 | B118: CR-127 | C118: Clerical Staff Union | D118: Workmen Dues | E118: Wages & Benefits | F118: 12000000 | G118: 11207700 | H118: 792300 | I118: 08-Dec-2025 | J118: 01-Dec-2025 | K118: Under Review | L118: 117 | M118: Tribunal Order | N118: K. Patel | P118: 23-Mar-2026
A119: 118 | B119: CR-128 | C119: Supervisory Staff Forum | D119: Workmen Dues | E119: Wages & Benefits | F119: 8000000 | G119: 7481218 | H119: 518782 | I119: 09-Dec-2025 | J119: 05-Dec-2025 | K119: Under Review | L119: 118 | M119: Resolution Plan B | N119: S. Gupta | P119: 23-Mar-2026
A120: 119 | B120: CR-129 | C120: Apprentice Welfare Committee | D120: Workmen Dues | E120: Wages & Benefits | F120: 12000000 | G120: 10699006 | H120: 1300994 | I120: 10-Dec-2025 | J120: 28-Feb-2026 | K120: Under Review | L120: 119 | M120: Settlement | N120: N. Singh | P120: 23-Mar-2026
... A125: 124 | B125: CR-134 | C125: Junior Staff Forum | D125: Workmen Dues | E125: Wages & Benefits | F125: 900000 | G125: 710676 | H125: 189324 | I125: 15-Dec-2025 | J125: 14-Feb-2026 | K125: Under Review | L125: 124 | M125: Going Concern | N125: K. Patel | P125: 23-Mar-2026
...

Sheet Category_Summary
A1: Category | B1: Total_Claims | C1: Total_Amount_INR | D1: Verified_Amount_INR | E1: Disputed_Amount_INR | F1: Avg_Claim_Amount | G1: %_of_Total | H1: Admitted | I1: Under_Review | J1: Pending | K1: Other
A2: Financial | B2: =COUNTIF(Master_Claims_Register!D2:D125,"Financial") -> 10 | C2: =SUMIF(Master_Claims_Register!D2:D125,"Financial",Master_Claims_Register!F2:F125) -> 1965000000 | D2: =SUMIF(Master_Claims_Register!D2:D125,"Financial",Master_Claims_Register!G2:G125) -> 1729440956 | E2: =SUMIF(Master_Claims_Register!D2:D125,"Financial",Master_Claims_Register!H2:H125) -> 235559044 | F2: =IF(B2>0,C2/B2,0) -> 196500000 | G2: =IF(C$6>0,C2/C$6,0) -> 0.65171968 | H2: =COUNTIFS(Master_Claims_Register!D2:D125,"Financial",Master_Claims_Register!K2:K125,"Admitted") -> 10 | I2: =COUNTIFS(Master_Claims_Register!D2:D125,"Financial",Master_Claims_Register!K2:K125,"Under Review") -> 0 | J2: =COUNTIFS(Master_Claims_Register!D2:D125,"Financial",Master_Claims_Register!K2:K125,"Pending") -> 0 | K2: =B2-H2-I2-J2 -> 0
A3: Operational | B3: =COUNTIF(Master_Claims_Register!D2:D125,"Operational") -> 80 | C3: =SUMIF(Master_Claims_Register!D2:D125,"Operational",Master_Claims_Register!F2:F125) -> 77000000 | D3: =SUMIF(Master_Claims_Register!D2:D125,"Operational",Master_Claims_Register!G2:G125) -> 66134009 | E3: =SUMIF(Master_Claims_Register!D2:D125,"Operational",Master_Claims_Register!H2:H125) -> 10865991 | F3: =IF(B3>0,C3/B3,0) -> 962500 | G3: =IF(C$6>0,C3/C$6,0) -> 0.025538125 | H3: =COUNTIFS(Master_Claims_Register!D2:D125,"Operational",Master_Claims_Register!K2:K125,"Admitted") -> 0 | I3: =COUNTIFS(Master_Claims_Register!D2:D125,"Operational",Master_Claims_Register!K2:K125,"Under Review") -> 5 | J3: =COUNTIFS(Master_Claims_Register!D2:D125,"Operational",Master_Claims_Register!K2:K125,"Pending") -> 75 | K3: =B3-H3-I3-J3 -> 0
A4: Statutory Dues | B4: =COUNTIF(Master_Claims_Register!D2:D125,"Statutory Dues") -> 19 | C4: =SUMIF(Master_Claims_Register!D2:D125,"Statutory Dues",Master_Claims_Register!F2:F125) -> 904000000 | D4: =SUMIF(Master_Claims_Register!D2:D125,"Statutory Dues",Master_Claims_Register!G2:G125) -> 821057390 | E4: =SUMIF(Master_Claims_Register!D2:D125,"Statutory Dues",Master_Claims_Register!H2:H125) -> 82942610 | F4: =IF(B4>0,C4/B4,0) -> 47578947 | G4: =IF(C$6>0,C4/C$6,0) -> 0.29982422 | H4: =COUNTIFS(Master_Claims_Register!D2:D125,"Statutory Dues",Master_Claims_Register!K2:K125,"Admitted") -> 0 | I4: =COUNTIFS(Master_Claims_Register!D2:D125,"Statutory Dues",Master_Claims_Register!K2:K125,"Under Review") -> 5 | J4: =COUNTIFS(Master_Claims_Register!D2:D125,"Statutory Dues",Master_Claims_Register!K2:K125,"Pending") -> 2 | K4: =B4-H4-I4-J4 -> 12
A5: Workmen Dues | B5: =COUNTIF(Master_Claims_Register!D2:D125,"Workmen Dues") -> 15 | C5: =SUMIF(Master_Claims_Register!D2:D125,"Workmen Dues",Master_Claims_Register!F2:F125) -> 69100000 | D5: =SUMIF(Master_Claims_Register!D2:D125,"Workmen Dues",Master_Claims_Register!G2:G125) -> 61827639 | E5: =SUMIF(Master_Claims_Register!D2:D125,"Workmen Dues",Master_Claims_Register!H2:H125) -> 7272361 | F5: =IF(B5>0,C5/B5,0) -> 4606666.7 | G5: =IF(C$6>0,C5/C$6,0) -> 0.02291798 | H5: =COUNTIFS(Master_Claims_Register!D2:D125,"Workmen Dues",Master_Claims_Register!K2:K125,"Admitted") -> 0 | I5: =COUNTIFS(Master_Claims_Register!D2:D125,"Workmen Dues",Master_Claims_Register!K2:K125,"Under Review") -> 15 | J5: =COUNTIFS(Master_Claims_Register!D2:D125,"Workmen Dues",Master_Claims_Register!K2:K125,"Pending") -> 0 | K5: =B5-H5-I5-J5 -> 0
A6: TOTAL | B6: =SUM(B2:B5) -> 124 | C6: =SUM(C2:C5) -> 3015100000 | D6: =SUM(D2:D5) -> 2678459994 | E6: =SUM(E2:E5) -> 336640006 | F6: =SUM(F2:F5) -> 2.4964811e+08 | G6: =SUM(G2:G5) -> 1 | H6: =SUM(H2:H5) -> 10 | I6: =SUM(I2:I5) -> 25 | ... K6: =SUM(K2:K5) -> 12

Sheet IT_Department_Detail
A1: S.No. | B1: Claim_ID | C1: Department_Unit | D1: Nature_of_Claim | E1: Assessment_Year | F1: Section_Reference | G1: Claim_Amount_INR | H1: Amount_Paid_INR | I1: Outstanding_INR | J1: Interest_u/s_234A | K1: Interest_u/s_234B | L1: Interest_u/s_234C | M1: Total_Interest_INR | N1: Penalty_Amount_INR | O1: Grand_Total_INR | P1: Date_of_Order | Q1: Date_of_Demand | R1: Appeal_Status | S1: Tribunal_Status | T1: High_Court_Status | U1: Current_Stage | V1: Priority_Level | W1: Officer_Name | X1: Officer_Designation | Y1: Contact | Z1: Remarks
A2: 1 | B2: IT-001 | C2: Assessment Wing | D2: IT Assessment AY 2020-21 | E2: 2020-21 | F2: 143(3) | G2: 250000000 | H2: 50000000 | I2: =G2-H2 -> 200000000 | J2: 17055546 | K2: 12948331 | L2: 19182287 | M2: =J2+K2+L2 -> 49186164 | N2: 2450537 | O2: =I2+M2+N2 -> 251636701 | P2: 46037 | Q2: 15-Jan-2026 | R2: Provisional Attachment | S2: CIT Appeals Pending | T2: N/A | U2: Provisional Attachment | V2: Low | W2: Shri V. Kumar | X2: ITO | Y2: 011-2348xxxx
A3: 2 | B3: IT-002 | C3: TDS Division | D3: TDS Default FY 2019-20 | E3: 2019-20 | F3: 201(1) | G3: 35000000 | H3: 5000000 | I3: =G3-H3 -> 30000000 | J3: 3120778 | K3: 2267515 | L3: 2076799 | M3: =J3+K3+L3 -> 7465092 | N3: 17375290 | O3: =I3+M3+N3 -> 54840382 | P3: 46042 | Q3: 20-Jan-2026 | R3: Under Review | S3: Not Filed | T3: N/A | U3: Under Review | V3: High | W3: Shri A.K. Singh | X3: ACIT | Y3: 011-2347xxxx
A4: 3 | B4: IT-003 | C4: Penalty Wing | D4: Concealment Penalty u/s 271(1)(c) | E4: 2020-21 | F4: 271(1)(c) | G4: 18000000 | H4: 0 | I4: =G4-H4 -> 18000000 | J4: 1092382 | K4: 1171504 | L4: 454648 | M4: =J4+K4+L4 -> 2718534 | N4: 2845100 | O4: =I4+M4+N4 -> 23563634 | P4: 46047 | Q4: 25-Jan-2026 | R4: Disputed | S4: CIT(A) Filed | T4: N/A | U4: Disputed | V4: High | W4: Smt. P. Devi | X4: DCIT | Y4: 011-2346xxxx
A5: 4 | B5: IT-004 | C5: Recovery Unit | D5: IT Recovery AY 2021-22 | E5: 2021-22 | F5: 220(1) | G5: 42000000 | H5: 8000000 | I5: =G5-H5 -> 34000000 | J5: 5114275 | K5: 3816518 | L5: 1080598 | M5: =J5+K5+L5 -> 10011391 | N5: 19564760 | O5: =I5+M5+N5 -> 63576151 | P5: 46054 | Q5: 01-Feb-2026 | R5: Notice Issued | S5: Stay Applied | T5: N/A | U5: Notice Issued | V5: Critical | W5: Shri V. Kumar | X5: ITO | Y5: 011-2348xxxx
A6: 5 | B6: IT-005 | C6: Assessment Wing | D6: IT Assessment AY 2022-23 | E6: 2022-23 | F6: 143(3) | G6: 55000000 | H6: 10000000 | I6: =G6-H6 -> 45000000 | J6: 4794934 | K6: 3909709 | L6: 3921750 | M6: =J6+K6+L6 -> 12626393 | N6: 14821925 | O6: =I6+M6+N6 -> 72448318 | P6: 46058 | Q6: 05-Feb-2026 | R6: Provisional Attachment | S6: Appeal Pending | T6: N/A | U6: Provisional Attachment | V6: High | W6: Smt. S. Rani | X6: JCIT | Y6: 011-2349xxxx
A7: 6 | B7: IT-006 | C7: International Tax Division | D7: Transfer Pricing Adjustment | E7: 2020-21 | F7: 92CA | G7: 120000000 | H7: 0 | I7: =G7-H7 -> 120000000 | J7: 13526446 | K7: 6529923 | L7: 4266244 | M7: =J7+K7+L7 -> 24322613 | N7: 6551258 | O7: =I7+M7+N7 -> 150873871 | P7: 46063 | Q7: 10-Feb-2026 | R7: Under Appeal | S7: ITAT Filed | T7: N/A | U7: Under Appeal | V7: Low | W7: Shri V. Kumar | X7: ITO | Y7: 011-2348xxxx
A8: 7 | B8: IT-007 | C8: TDS Division | D8: TDS Short Deduction FY 2020-21 | E8: 2020-21 | F8: 201(1A) | G8: 28000000 | H8: 3000000 | I8: =G8-H8 -> 25000000 | J8: 3905592 | K8: 1017771 | L8: 961514 | M8: =J8+K8+L8 -> 5884877 | N8: 3995247 | O8: =I8+M8+N8 -> 34880124 | P8: 46068 | Q8: 15-Feb-2026 | R8: Under Review | S8: Not Filed | T8: N/A | U8: Under Review | V8: Low | W8: Smt. S. Rani | X8: JCIT | Y8: 011-2349xxxx
A9: 8 | B9: IT-008 | C9: Reassessment Cell | D9: Reassessment u/s 148 AY 2019-20 | E9: 2019-20 | F9: 148/147 | G9: 75000000 | H9: 0 | I9: =G9-H9 -> 75000000 | J9: 10331078 | K9: 3767282 | L9: 2667908 | M9: =J9+K9+L9 -> 16766268 | N9: 24255604 | O9: =I9+M9+N9 -> 116021872 | P9: 45981 | Q9: 20-Feb-2026 | R9: Notice Issued | S9: Challenge Filed | T9: N/A | U9: Notice Issued | V9: Low | W9: Shri A.K. Singh | X9: ACIT | Y9: 011-2347xxxx
A10: 9 | B10: IT-009 | C10: Penalty Wing | D10: Concealment Penalty AY 2021-22 | E10: 2021-22 | F10: 271(1)(c) | G10: 32000000 | H10: 0 | I10: =G10-H10 -> 32000000 | J10: 2607871 | K10: 991272 | L10: 1871455 | M10: =J10+K10+L10 -> 5470598 | N10: 13134831 | O10: =I10+M10+N10 -> 50605429 | P10: 46078 | Q10: 25-Feb-2026 | R10: Disputed | S10: CIT(A) Pending | T10: N/A | U10: Disputed | V10: Low | W10: Smt. P. Devi | X10: DCIT | Y10: 011-2346xxxx
A11: 10 | B11: IT-010 | C11: Demand & Collection | D11: Outstanding IT Demand AY 2023-24 | E11: 2023-24 | F11: 156 | G11: 90000000 | H11: 15000000 | I11: =G11-H11 -> 75000000 | J11: 12160428 | K11: 7490447 | L11: 5356119 | M11: =J11+K11+L11 -> 25006994 | N11: 25128221 | O11: =I11+M11+N11 -> 125135215 | P11: 46082 | Q11: 01-Mar-2026 | R11: Provisional Attachment | S11: Rectification Filed | T11: N/A | U11: Provisional Attachment | V11: Critical | W11: Smt. S. Rani | X11: JCIT | Y11: 011-2349xxxx
A12: 11 | B12: IT-011 | C12: Prosecution Wing | D12: Prosecution u/s 276C | E12: 2019-20 | F12: 276C | G12: 0 | H12: 0 | I12: =G12-H12 -> 0 | J12: 0 | K12: 0 | L12: 0 | M12: =J12+K12+L12 -> 0 | N12: 0 | O12: =I12+M12+N12 -> 0 | P12: 46086 | Q12: 05-Mar-2026 | R12: Criminal Proceedings | S12: Sessions Court | T12: N/A | U12: Criminal Proceedings | V12: Medium | W12: Smt. P. Devi | X12: DCIT | Y12: 011-2346xxxx
A13: 12 | B13: IT-012 | C13: Faceless Assessment Unit | D13: Faceless Assessment AY 2024-25 | E13: 2024-25 | F13: 144B | G13: 45000000 | H13: 5000000 | I13: =G13-H13 -> 40000000 | J13: 5495815 | K13: 4330580 | L13: 3573083 | M13: =J13+K13+L13 -> 13399478 | N13: 10061154 | O13: =I13+M13+N13 -> 63460632 | P13: 45940 | Q13: 10-Mar-2026 | R13: Under Review | S13: DRP Filed | T13: N/A | U13: Under Review | V13: Critical | W13: Shri A.K. Singh | X13: ACIT | Y13: 011-2347xxxx
... A19: 18 | B19: IT-018 | C19: International Tax Division | D19: APA Non-Compliance | E19: 2021-22 | F19: 92CD | G19: 95000000 | H19: 0 | I19: =G19-H19 -> 95000000 | J19: 13708791 | K19: 5415429 | L19: 6848581 | M19: =J19+K19+L19 -> 25972801 | N19: 13397230 | O19: =I19+M19+N19 -> 134370031 | P19: 46106 | Q19: 25-Mar-2026 | R19: Disputed | S19: MAP Invoked | T19: N/A | U19: Disputed | V19: Medium | W19: Shri A.K. Singh | X19: ACIT | Y19: 011-2347xxxx
F20: TOTALS | G20: =SUM(G2:G19) -> 1148000000 | H20: =SUM(H2:H19) -> 98500000 | I20: =SUM(I2:I19) -> 1049500000 | J20: =SUM(J2:J19) -> 112219041 | K20: =SUM(K2:K19) -> 67981661 | L20: =SUM(L2:L19) -> 70797524 | M20: =SUM(M2:M19) -> 250998226 | N20: =SUM(N2:N19) -> 219684392 | O20: =SUM(O2:O19) -> 1520182618

Sheet Priority_Waterfall
A1: Priority_Rank | B1: Category | C1: IBC_Section | D1: Description | E1: Total_Amount_INR | F1: %_of_Total_Claims | G1: Cumulative_% | H1: Recovery_Estimate_% | I1: Estimated_Recovery_INR | J1: Shortfall_INR
A2: 1 | B2: CIRP Costs | C2: Section 53(1)(a) | D2: IRP/RP fees, legal costs, valuation | E2: 25000000 | F2: =IF(E$11>0,E2/E$11,0) -> 1 | G2: =F2 -> 1 | H2: 1 | I2: =E2*H2 -> 25000000 | J2: =E2-I2 -> 0
A3: 2 | B3: Workmen Dues (24 months) | C3: Section 53(1)(b)(i) | D3: Wages for 24 months preceding liquidation | E3: 0 | F3: =IF(E$11>0,E3/E$11,0) -> 0 | G3: =G2+F3 -> 1 | H3: 0.95 | I3: =E3*H3 -> 0 | J3: =E3-I3 -> 0
A4: 3 | B4: Financial Creditors | C4: Section 53(1)(b)(ii) | D4: All admitted financial claims | E4: 0 | F4: =IF(E$11>0,E4/E$11,0) -> 0 | G4: =G3+F4 -> 1 | H4: 0.45 | I4: =E4*H4 -> 0 | J4: =E4-I4 -> 0
A5: 4 | B5: Workmen Dues (>24 months) | C5: Section 53(1)(c) | D5: Remaining workmen dues | E5: 0 | F5: =IF(E$11>0,E5/E$11,0) -> 0 | G5: =G4+F5 -> 1 | H5: 0.9 | I5: =E5*H5 -> 0 | J5: =E5-I5 -> 0
A6: 5 | B6: Operational Creditors | C6: Section 53(1)(d) | D6: All operational creditor claims | E6: 0 | F6: =IF(E$11>0,E6/E$11,0) -> 0 | G6: =G5+F6 -> 1 | H6: 0.15 | I6: =E6*H6 -> 0 | J6: =E6-I6 -> 0
A7: 6 | B7: Statutory Dues - Govt | C7: Section 53(1)(e) | D7: Central/State Govt statutory dues | E7: 0 | F7: =IF(E$11>0,E7/E$11,0) -> 0 | G7: =G6+F7 -> 1 | H7: 0.1 | I7: =E7*H7 -> 0 | J7: =E7-I7 -> 0
A8: 7 | B8: Other Creditors | C8: Section 53(1)(f) | D8: Any remaining claims | E8: 0 | F8: =IF(E$11>0,E8/E$11,0) -> 0 | G8: =G7+F8 -> 1 | H8: 0.05 | I8: =E8*H8 -> 0 | J8: =E8-I8 -> 0
A9: 8 | B9: Preference Shareholders | C9: Section 53(1)(g) | D9: Preference share capital | E9: 0 | F9: =IF(E$11>0,E9/E$11,0) -> 0 | G9: =G8+F9 -> 1 | H9: 0 | I9: =E9*H9 -> 0 | J9: =E9-I9 -> 0
A10: 9 | B10: Equity Shareholders | C10: Section 53(1)(h) | D10: Equity share capital | E10: 0 | F10: =IF(E$11>0,E10/E$11,0) -> 0 | G10: =G9+F10 -> 1 | H10: 0 | I10: =E10*H10 -> 0 | J10: =E10-I10 -> 0
D11: TOTAL | E11: =SUM(E2:E10) -> 25000000 | I11: =SUM(I2:I10) -> 25000000 | J11: =SUM(J2:J10) -> 0

Sheet CIRP_Timeline
A1: S.No. | B1: Milestone | C1: IBC_Section | D1: Statutory_Deadline | E1: Actual_Date | F1: Days_Elapsed | G1: Days_Remaining | H1: Status | I1: Responsible_Person | J1: Documents | K1: Remarks
A2: 1 | B2: CIRP Commencement Order | C2: Section 7/9/10 | D2: 01-Oct-2025 | E2: 01-Oct-2025 | H2: Completed | I2: NCLT Bench
A3: 2 | B3: Public Announcement | C3: Section 15 | D3: 05-Oct-2025 | E3: 04-Oct-2025 | H3: Completed | I3: IRP R. Sharma
A4: 3 | B4: Claims Submission Deadline | C4: Section 15(1)(c) | D4: 15-Nov-2025 | E4: 15-Nov-2025 | H4: Completed | I4: IRP R. Sharma
A5: 4 | B5: Verification of Claims | C5: Section 18(1)(b) | D5: 30-Nov-2025 | E5: 28-Nov-2025 | H5: Completed | I5: IRP R. Sharma
A6: 5 | B6: CoC Formation | C6: Section 21 | D6: 05-Dec-2025 | E6: 05-Dec-2025 | H6: Completed | I6: IRP R. Sharma
A7: 6 | B7: First CoC Meeting | C7: Reg 17 | D7: 10-Dec-2025 | E7: 10-Dec-2025 | H7: Completed | I7: RP A. Verma
A8: 7 | B8: Information Memorandum | C8: Section 29(2) | D8: 15-Jan-2026 | E8: 10-Jan-2026 | H8: Completed | I8: RP A. Verma
A9: 8 | B9: Expression of Interest Deadline | C9: Reg 36A | D9: 15-Feb-2026 | H9: In Progress | I9: RP A. Verma
A10: 9 | B10: Provisional List of RAs | C10: Reg 36A(4) | D10: 01-Mar-2026 | H10: Pending | I10: RP A. Verma
A11: 10 | B11: Resolution Plan Submission | C11: Section 30(1) | D11: 15-Mar-2026 | H11: Pending | I11: Resolution Applicants
A12: 11 | B12: CoC Voting on Plan | C12: Section 30(4) | D12: 30-Mar-2026 | H12: Pending | I12: CoC Members
A13: 12 | B13: NCLT Approval | C13: Section 31(1) | D13: 15-Apr-2026 | H13: Pending | I13: NCLT
A14: 13 | B14: IT Dept Claims Hearing | C14: NCLT Order | D14: 20-Mar-2026 | H14: Pending | I14: IT Department
A15: 14 | B15: IT Dept Assessment Review | C15: Section 53 | D15: 25-Mar-2026 | H15: Pending | I15: IT Dept/RP
A16: 15 | B16: 180-Day CIRP Deadline | C16: Section 12(1) | D16: 30-Mar-2026 | H16: Critical | I16: NCLT/RP
A17: 16 | B17: Extension Application (if needed) | C17: Section 12(2) | D17: 30-Mar-2026 | H17: Contingency | I17: RP A. Verma
A18: 17 | B18: 270-Day Final Deadline | C18: Section 12(3) | D18: 28-Jun-2026 | H18: Contingency | I18: NCLT

Sheet Audit_Log
A1: S.No. | B1: Date | C1: Time | D1: Action | E1: Claim_ID | F1: Modified_By | G1: Old_Value | H1: New_Value | I1: Reason | J1: Approved_By
A2: 1 | B2: 01-Oct-2025 | C2: 09:00 | D2: CIRP Initiated | E2: ALL | F2: System | G2: N/A | H2: Active | I2: NCLT Order | J2: NCLT Bench
A3: 2 | B3: 04-Oct-2025 | C3: 10:30 | D3: Public Announcement Published | E3: ALL | F3: IRP R. Sharma | G3: Draft | H3: Published | I3: Statutory Requirement | J3: CoC
A4: 3 | B4: 15-Nov-2025 | C4: 17:00 | D4: Claims Window Closed | E4: ALL | F4: System | G4: Open | H4: Closed | I4: Deadline | J4: IRP R. Sharma
A5: 4 | B5: 20-Nov-2025 | C5: 14:15 | D5: Claim Amount Updated | E5: CR-001 | F5: IRP R. Sharma | G5: 48,00,00,000 | H5: 50,00,00,000 | I5: Revised Statement | J5: CoC Chair
A6: 5 | B6: 28-Nov-2025 | C6: 11:00 | D6: Claims Verified | E6: CR-001 to CR-010 | F6: IRP R. Sharma | G6: Unverified | H6: Verified | I6: Section 18 Compliance | J6: IRP R. Sharma
A7: 6 | B7: 05-Dec-2025 | C7: 16:00 | D7: CoC Formed | E7: N/A | F7: RP A. Verma | G7: N/A | H7: Constituted | I7: Section 21 | J7: NCLT
A8: 7 | B8: 15-Jan-2026 | C8: 10:00 | D8: IT Dept Claim Received | E8: CR-092 | F8: RP A. Verma | G8: N/A | H8: ₹25 Cr | I8: IT Assessment Order | J8: RP A. Verma
A9: 8 | B9: 20-Jan-2026 | C9: 11:30 | D9: IT Dept TDS Claim Added | E9: CR-100 | F9: RP A. Verma | G9: N/A | H9: ₹3.5 Cr | I9: TDS Default Notice | J9: RP A. Verma
A10: 9 | B10: 25-Jan-2026 | C10: 14:00 | D10: IT Dept Penalty Claim Added | E10: CR-101 | F10: RP A. Verma | G10: N/A | H10: ₹1.8 Cr | I10: Penalty Order | J10: RP A. Verma
A11: 10 | B11: 01-Feb-2026 | C11: 09:45 | D11: IT Dept Recovery Notice | E11: CR-102 | F11: IT Dept | G11: N/A | H11: ₹4.2 Cr | I11: Recovery u/s 220 | J11: RP A. Verma
